Traceback (most recent call last):
  File "main.py", line 348, in <module>
    main()
  File "main.py", line 186, in main
    manager = DistributedManager(args)
  File "/data/jinggu/project/Pretraining_GPT/distributed_utils.py", line 30, in __init__
    torch.distributed.init_process_group(backend='nccl')
  File "/home/jinggu/.local/lib/python3.7/site-packages/torch/distributed/distributed_c10d.py", line 406, in init_process_group
    store, rank, world_size = next(rendezvous(url))
  File "/home/jinggu/.local/lib/python3.7/site-packages/torch/distributed/rendezvous.py", line 143, in _env_rendezvous_handler
    store = TCPStore(master_addr, master_port, world_size, start_daemon)
RuntimeError: Address already in use
Traceback (most recent call last):
  File "/home/jinggu/anaconda3/envs/pretraining_env/lib/python3.7/runpy.py", line 193, in _run_module_as_main
    "__main__", mod_spec)
  File "/home/jinggu/anaconda3/envs/pretraining_env/lib/python3.7/runpy.py", line 85, in _run_code
    exec(code, run_globals)
  File "/home/jinggu/.local/lib/python3.7/site-packages/torch/distributed/launch.py", line 246, in <module>
    main()
  File "/home/jinggu/.local/lib/python3.7/site-packages/torch/distributed/launch.py", line 242, in main
    cmd=cmd)
subprocess.CalledProcessError: Command '['/home/jinggu/anaconda3/envs/pretraining_env/bin/python', '-u', 'main.py', '--local_rank=0', '--fp16', '--model_size=medium', '--loss_type=all', '--batch_size=7']' returned non-zero exit status 1.
